Workbook

Sheet Cover
A1: PDO ISO/IEC 20000-1 Engagement
A2: Program Plan
A4: Program Start Date | B4: 46281 | C4: (Tentative)
A5: Planning Horizon/ Duration | B5: 40 weeks based on Schedule Summary activity range
A6: Deliverables | B6: - Project Charter - Detailed Schedule - Weekly Summary - Gantt Chart based on Resource Loading - Resource Loading

Sheet Project Charter
A1: Project Charter - PDO ISO/IEC 20000-1 Engagement
A2: Prepared directly from the Resource Loading sheet in this workbook
A4: Charter Element | B4: Description
A5: Project Title | B5: PDO ISO/IEC 20000-1 Certification Engagement
A6: Purpose | B6: Plan, mobilize, assess, optimize, implement, train, audit and support certification readiness for PDO IT service management practices.
A7: Primary Planning Source | B7: Resource Loading sheet in the same workbook
A8: Project Start Date | B8: 46281
A9: Project End Date | B9: 46558
A10: Planning Duration | B10: 40 weeks
A11: Total Planned Resource Loading PD | B11: =SUM('Detailed Schedule'!G2:G67) -> 745
A12: Peak Weekly PD | B12: =MAX('Weekly Summary'!H2:H41) -> 30
A13: Peak FTE Equivalent | B13: 6
A14: Key Resource Types | B14: SME/ PM, Senior Consultant, Consultant 1, Consultant 2 and Omani Trainees
A15: Governance Cadence | B15: Weekly project status, RAID/action tracking and steering updates through project management activity.
A16: Success Criteria | B16: Completion of mobilization readiness, gap assessment, optimized documentation, implementation evidence, training, internal audit, management review and certification support.
A19: Project Objectives
A20: Objectives | B20: Establish engagement governance and confirm scope, stakeholders, evidence access and working calendar.
B21: Understand the PDO IDD operating model, service landscape, dependencies and site context before formal gap assessment.
B22: Execute service-wise gap assessment and optimize policies, procedures and evidence maps.
B23: Support implementation consulting, training, internal audit readiness, management review and certification audit response.
B24: Enable knowledge transfer through Omani trainee participation during execution.
A27: Activities | B27: Start Week | C27: End Week | D27: Start Date | E27: End Date | F27: Planned PD
A28: Initiation & Governance | B28: 1 | C28: 2 | D28: 46281 | E28: 46292 | F28: 8
A29: Understanding of PDO Ecosystem | B29: 2 | C29: 4 | D29: 46288 | E29: 46306 | F29: 12
A30: PDO Team Commitment and Availability for Gap Analysis | B30: 5 | C30: 7 | D30: 46309 | E30: 46327 | F30: 12
A31: Mobilization and Engagement Readiness | B31: 7 | C31: 11 | D31: 46323 | E31: 46355 | F31: 22
A32: Project Management Activity | B32: 7 | C32: 38 | D32: 46323 | E32: 46544 | F32: 69
A33: Gap Assessment | B33: 12 | C33: 17 | D33: 46358 | E33: 46397 | F33: 22
A34: Policy & Procedure Optimization | B34: 18 | C34: 25 | D34: 46400 | E34: 46453 | F34: 36
A35: Implementation Consulting | B35: 19 | C35: 36 | D35: 46407 | E35: 46530 | F35: 220
A36: Domestic Travel | B36: 26 | C36: 40 | D36: 46456 | E36: 46558 | F36: 24
A37: Training & Enablement | B37: 27 | C37: 31 | D37: 46463 | E37: 46495 | F37: 22
A38: Internal Audit & Readiness | B38: 34 | C38: 37 | D38: 46512 | E38: 46537 | F38: 22
A39: Management Review | B39: 38 | C39: 38 | D39: 46540 | E39: 46544 | F39: 4
... A41: Trainee Support | B41: 16 | C41: 40 | D41: 46386 | E41: 46558 | F41: 250
A44: Key Assumptions and Risks | B44: Impact / Mitigation
A45: PDO SME availability is confirmed as per planned weeks | B45: Slippage in availability can affect gap assessment, evidence readiness and certification support dates.
A46: Identification of Certification of Certification Body | B46: Delay in Identifiying Certifying Body may impact the project completion timelines.
A47: Resource loading is treated as the controlling planning baseline | B47: Detailed schedule and Gantt are derived from first and last non-zero weekly loading per activity.
A48: Domestic travel/site access is available during planned windows | B48: Travel and site coordination should be locked four weeks before relevant activity windows.
...

Sheet Detailed Schedule
A1: Detailed Schedule - Derived from Resource Loading
A2: Start and end weeks are calculated from the first and last non-zero weekly loading for each activity
A4: ID | B4: Phase | C4: Activity | D4: Service / Scope | E4: Resource Type | F4: Planned PD | G4: Loaded PD | H4: Variance PD | I4: Start Week | J4: End Week | K4: Start Date | L4: End Date | M4: Duration Weeks | N4: Predecessor / Dependency | O4: Key Deliverable | P4: Status / Remarks
A5: 1 | B5: Initiation & Governance | C5: Kick-off, scope confirmation, governance, evidence tracker and working calendar | D5: All services | E5: SME | F5: 8 | G5: 8 | H5: 0 | I5: 1 | J5: 2 | K5: 46281 | L5: 46292 | M5: 2 | N5: Project approval | O5: Project charter, governance cadence, kickoff pack and evidence tracker | P5: Planned
A6: 2 | B6: Understanding of PDO Ecosystem | C6: Understand IDD operating model, service landscape, stakeholders, dependencies, suppliers and site context | D6: All services | E6: SME | F6: 12 | G6: 12 | H6: 0 | I6: 2 | J6: 4 | K6: 46288 | L6: 46306 | M6: 3 | N6: Initiation & Governance | O6: PDO IDD ecosystem assessment note, stakeholder map and service landscape summary | P6: Planned
A7: 3 | B7: PDO Team Commitment and Availability for Gap Analysis | C7: Confirm service owners, process owners, SME participation, evidence owners and workshop calendar | D7: All services | E7: SME | F7: 12 | G7: 12 | H7: 0 | I7: 5 | J7: 7 | K7: 46309 | L7: 46327 | M7: 3 | N7: Understanding of PDO Ecosystem | O7: Confirmed service/process owner availability and gap assessment workshop calendar | P7: Planned
A8: 4 | B8: Mobilization and Engagement Readiness | C8: Onboarding, access readiness, evidence request follow-up, questionnaire clarification and site/audit coordination | D8: All services | E8: SME | F8: 22 | G8: 22 | H8: 0 | I8: 7 | J8: 11 | K8: 46323 | L8: 46355 | M8: 5 | N8: PDO Team Commitment and Availability for Gap Analysis | O8: Mobilization readiness confirmation, access readiness and evidence request tracker | P8: Planned
A9: 5 | B9: Project Management Activity | C9: Governance tracking, status reporting, issues, risks, stakeholder communication and coordination | D9: All services | E9: SME / PM | F9: 69 | G9: 69 | H9: 0 | I9: 7 | J9: 38 | K9: 46323 | L9: 46544 | M9: 32 | N9: Ongoing governance | O9: Weekly status report, RAID log, action tracker and steering updates | P9: Planned
A10: 6 | B10: Gap Assessment | C10: Gap Assessment - Infrastructure Services | D10: Infrastructure Services | E10: SME | F10: 2 | G10: 2 | H10: 0 | I10: 12 | J10: 12 | K10: 46358 | L10: 46362 | M10: 1 | N10: Mobilization and Engagement Readiness | O10: Service-level gap observations, evidence review results and prioritized action list | P10: Planned
A11: 7 | B11: Gap Assessment | C11: Gap Assessment - End User Support | D11: End User Support | E11: SME | F11: 8 | G11: 8 | H11: 0 | I11: 13 | J11: 14 | K11: 46365 | L11: 46376 | M11: 2 | N11: Mobilization and Engagement Readiness | O11: Service-level gap observations, evidence review results and prioritized action list | P11: Planned
A12: 8 | B12: Gap Assessment | C12: Gap Assessment - Application Support | D12: Application Support | E12: SME | F12: 2 | G12: 2 | H12: 0 | I12: 15 | J12: 15 | K12: 46379 | L12: 46383 | M12: 1 | N12: Mobilization and Engagement Readiness | O12: Service-level gap observations, evidence review results and prioritized action list | P12: Planned
A13: 9 | B13: Gap Assessment | C13: Gap Assessment - Field Communication Systems | D13: Field Communication Systems | E13: SME | F13: 2 | G13: 2 | H13: 0 | I13: 15 | J13: 15 | K13: 46379 | L13: 46383 | M13: 1 | N13: Mobilization and Engagement Readiness | O13: Service-level gap observations, evidence review results and prioritized action list | P13: Planned
A14: 10 | B14: Gap Assessment | C14: Gap Assessment - Data Centre | D14: Data Centre | E14: SME | F14: 2 | G14: 2 | H14: 0 | I14: 16 | J14: 16 | K14: 46386 | L14: 46390 | M14: 1 | N14: Mobilization and Engagement Readiness | O14: Service-level gap observations, evidence review results and prioritized action list | P14: Planned
A15: 11 | B15: Gap Assessment | C15: Gap Assessment - SAP Support | D15: SAP Support | E15: SME | F15: 2 | G15: 2 | H15: 0 | I15: 16 | J15: 16 | K15: 46386 | L15: 46390 | M15: 1 | N15: Mobilization and Engagement Readiness | O15: Service-level gap observations, evidence review results and prioritized action list | P15: Planned
A16: 12 | B16: Gap Assessment | C16: Gap Assessment - Network Services | D16: Network Services | E16: SME | F16: 2 | G16: 2 | H16: 0 | I16: 17 | J16: 17 | K16: 46393 | L16: 46397 | M16: 1 | N16: Mobilization and Engagement Readiness | O16: Service-level gap observations, evidence review results and prioritized action list | P16: Planned
... A67: 63 | B67: Trainee Support | C67: Omani Trainee 2 | D67: All services | E67: Trainee | F67: 125 | G67: 125 | H67: 0 | I67: 16 | J67: 40 | K67: 46386 | L67: 46558 | M67: 25 | N67: Mobilization and trainee onboarding | O67: Trainee activity log, knowledge transfer records and evidence support output | P67: Planned

Sheet Weekly Summary
A1: Weekly Summary and Resource Loading Profile
A2: Weekly totals derived from the Resource Loading sheet
A4: Week | B4: Week Start | C4: Week End | D4: SME PD | E4: Consultant PD | F4: Trainee PD | G4: Travel PD | H4: Total PD | I4: Total FTE | J4: Key Active Activities
A5: 1 | B5: 46281 | C5: 46285 | D5: 5 | E5: 0 | F5: 0 | G5: 0 | H5: =SUM(D5:G5) -> 5 | I5: =H5/5 -> 1 | J5: Initiation & Governance
A6: 2 | B6: 46286 | C6: 46290 | D6: 5 | E6: 0 | F6: 0 | G6: 0 | H6: =SUM(D6:G6) -> 5 | I6: =H6/5 -> 1 | J6: Initiation & Governance; Understanding of PDO Ecosystem
A7: 3 | B7: 46293 | C7: 46297 | D7: 5 | E7: 0 | F7: 0 | G7: 0 | H7: =SUM(D7:G7) -> 5 | I7: =H7/5 -> 1 | J7: Understanding of PDO Ecosystem
A8: 4 | B8: 46300 | C8: 46304 | D8: 5 | E8: 0 | F8: 0 | G8: 0 | H8: =SUM(D8:G8) -> 5 | I8: =H8/5 -> 1 | J8: Understanding of PDO Ecosystem
A9: 5 | B9: 46307 | C9: 46311 | D9: 5 | E9: 0 | F9: 0 | G9: 0 | H9: =SUM(D9:G9) -> 5 | I9: =H9/5 -> 1 | J9: PDO Team Commitment and Availability for Gap Analysis
A10: 6 | B10: 46314 | C10: 46318 | D10: 5 | E10: 0 | F10: 0 | G10: 0 | H10: =SUM(D10:G10) -> 5 | I10: =H10/5 -> 1 | J10: PDO Team Commitment and Availability for Gap Analysis
A11: 7 | B11: 46321 | C11: 46325 | D11: 5 | E11: 0 | F11: 0 | G11: 0 | H11: =SUM(D11:G11) -> 5 | I11: =H11/5 -> 1 | J11: PDO Team Commitment and Availability for Gap Analysis; Mobilization and Engagement Readiness; Project Management Activity
A12: 8 | B12: 46328 | C12: 46332 | D12: 5 | E12: 0 | F12: 0 | G12: 0 | H12: =SUM(D12:G12) -> 5 | I12: =H12/5 -> 1 | J12: Mobilization and Engagement Readiness
A13: 9 | B13: 46335 | C13: 46339 | D13: 5 | E13: 0 | F13: 0 | G13: 0 | H13: =SUM(D13:G13) -> 5 | I13: =H13/5 -> 1 | J13: Mobilization and Engagement Readiness
A14: 10 | B14: 46342 | C14: 46346 | D14: 5 | E14: 0 | F14: 0 | G14: 0 | H14: =SUM(D14:G14) -> 5 | I14: =H14/5 -> 1 | J14: Mobilization and Engagement Readiness
A15: 11 | B15: 46349 | C15: 46353 | D15: 5 | E15: 0 | F15: 0 | G15: 0 | H15: =SUM(D15:G15) -> 5 | I15: =H15/5 -> 1 | J15: Mobilization and Engagement Readiness
A16: 12 | B16: 46356 | C16: 46360 | D16: 5 | E16: 0 | F16: 0 | G16: 0 | H16: =SUM(D16:G16) -> 5 | I16: =H16/5 -> 1 | J16: Project Management Activity; Gap Assessment
... A44: 40 | B44: 46552 | C44: 46556 | D44: 2 | E44: 9 | F44: 10 | G44: 4 | H44: =SUM(D44:G44) -> 25 | I44: =H44/5 -> 5 | J44: Certification Support; Domestic Travel; Trainee Support
H45: =SUM(H5:H44) -> 745 | I45: =H45/5 -> 149

Sheet Gantt Chart
A1: Gantt Chart - Derived from Resource Loading
A2: Bars represent active weeks from the weekly resource loading baseline
A4: ID | B4: Phase | C4: Activity | D4: Resource Type | E4: Planned PD | F4: Start Week | G4: End Week | H4: W1 16-Sep | I4: W2 23-Sep | J4: W3 30-Sep | K4: W4 07-Oct | L4: W5 14-Oct | M4: W6 21-Oct | N4: W7 28-Oct | O4: W8 04-Nov | P4: W9 11-Nov | Q4: W10 18-Nov | R4: W11 25-Nov | S4: W12 02-Dec | T4: W13 09-Dec | U4: W14 16-Dec | V4: W15 23-Dec | W4: W16 30-Dec | X4: W17 06-Jan | Y4: W18 13-Jan | Z4: W19 20-Jan | AA4: W20 27-Jan | AB4: W21 03-Feb | AC4: W22 10-Feb | AD4: W23 17-Feb | AE4: W24 24-Feb | AF4: W25 03-Mar | AG4: W26 10-Mar | AH4: W27 17-Mar | AI4: W28 24-Mar | AJ4: W29 31-Mar | AK4: W30 07-Apr | AL4: W31 14-Apr | AM4: W32 21-Apr | AN4: W33 28-Apr | AO4: W34 05-May | AP4: W35 12-May | AQ4: W36 19-May | AR4: W37 26-May | AS4: W38 02-Jun | AT4: W39 09-Jun | AU4: W40 16-Jun
A5: 1 | B5: Initiation & Governance | C5: Kick-off, scope confirmation, governance, evidence tracker and working calendar | D5: SME | E5: 8 | F5: 1 | G5: 2 | H5: 5 | I5: 3
A6: 2 | B6: Understanding of PDO Ecosystem | C6: Understand IDD operating model, service landscape, stakeholders, dependencies, suppliers and site context | D6: SME | E6: 12 | F6: 2 | G6: 4 | I6: 2 | J6: 5 | K6: 5
A7: 3 | B7: PDO Team Commitment and Availability for Gap Analysis | C7: Confirm service owners, process owners, SME participation, evidence owners and workshop calendar | D7: SME | E7: 12 | F7: 5 | G7: 7 | L7: 5 | M7: 5 | N7: 2
A8: 4 | B8: Mobilization and Engagement Readiness | C8: Onboarding, access readiness, evidence request follow-up, questionnaire clarification and site/audit coordination | D8: SME | E8: 22 | F8: 7 | G8: 11 | N8: 2 | O8: 5 | P8: 5 | Q8: 5 | R8: 5
A9: 5 | B9: Project Management Activity | C9: Governance tracking, status reporting, issues, risks, stakeholder communication and coordination | D9: SME / PM | E9: 69 | F9: 7 | G9: 38 | N9: 1 | S9: 3 | U9: 2 | V9: 1 | W9: 1 | X9: 1 | Y9: 5 | Z9: 5 | AA9: 5 | AB9: 5 | AC9: 5 | AD9: 5 | AE9: 5 | AF9: 5 | AG9: 5 | AL9: 3 | AM9: 5 | AN9: 5 | AR9: 1 | AS9: 1
A10: 6 | B10: Gap Assessment | C10: Gap Assessment - Infrastructure Services | D10: SME | E10: 2 | F10: 12 | G10: 12 | S10: 2
A11: 7 | B11: Gap Assessment | C11: Gap Assessment - End User Support | D11: SME | E11: 8 | F11: 13 | G11: 14 | T11: 5 | U11: 3
A12: 8 | B12: Gap Assessment | C12: Gap Assessment - Application Support | D12: SME | E12: 2 | F12: 15 | G12: 15 | V12: 2
A13: 9 | B13: Gap Assessment | C13: Gap Assessment - Field Communication Systems | D13: SME | E13: 2 | F13: 15 | G13: 15 | V13: 2
A14: 10 | B14: Gap Assessment | C14: Gap Assessment - Data Centre | D14: SME | E14: 2 | F14: 16 | G14: 16 | W14: 2
A15: 11 | B15: Gap Assessment | C15: Gap Assessment - SAP Support | D15: SME | E15: 2 | F15: 16 | G15: 16 | W15: 2
A16: 12 | B16: Gap Assessment | C16: Gap Assessment - Network Services | D16: SME | E16: 2 | F16: 17 | G16: 17 | X16: 2
A17: 13 | B17: Gap Assessment | C17: Gap Assessment - Cyber Security Operations | D17: SME | E17: 2 | F17: 17 | G17: 17 | X17: 2
A18: 14 | B18: Policy & Procedure Optimization | C18: Policy & Procedure Optimization - Infrastructure Services | D18: Sr Consultant | E18: 4 | F18: 18 | G18: 18 | Y18: 4
A19: 15 | B19: Policy & Procedure Optimization | C19: Policy & Procedure Optimization - End User Support | D19: Sr Consultant | E19: 8 | F19: 18 | G19: 20 | Y19: 1 | Z19: 5 | AA19: 2
A20: 16 | B20: Policy & Procedure Optimization | C20: Policy & Procedure Optimization - Application Support | D20: Sr Consultant | E20: 4 | F20: 20 | G20: 20 | AA20: 4
A21: 17 | B21: Policy & Procedure Optimization | C21: Policy & Procedure Optimization - Field Communication Systems | D21: Sr Consultant | E21: 4 | F21: 21 | G21: 21 | AB21: 4
A22: 18 | B22: Policy & Procedure Optimization | C22: Policy & Procedure Optimization - Data Centre | D22: Sr Consultant | E22: 4 | F22: 22 | G22: 22 | AC22: 4
A23: 19 | B23: Policy & Procedure Optimization | C23: Policy & Procedure Optimization - SAP Support | D23: Sr Consultant | E23: 4 | F23: 23 | G23: 23 | AD23: 4
A24: 20 | B24: Policy & Procedure Optimization | C24: Policy & Procedure Optimization - Network Services | D24: Sr Consultant | E24: 4 | F24: 24 | G24: 24 | AE24: 4
A25: 21 | B25: Policy & Procedure Optimization | C25: Policy & Procedure Optimization - Cyber Security Operations | D25: Sr Consultant | E25: 4 | F25: 25 | G25: 25 | AF25: 4
A26: 22 | B26: Implementation Consulting | C26: Implementation Consulting - Infrastructure Services | D26: Sr Consultant | E26: 21 | F26: 21 | G26: 29 | AB26: 1 | AC26: 1 | AD26: 1 | AE26: 1 | AF26: 1 | AG26: 4 | AH26: 4 | AI26: 4 | AJ26: 4
A27: 23 | B27: Domestic Travel | C27: Domestic Travel for Implementation- 4 Sites North | D27: Sr Consultant | E27: 4 | F27: 26 | G27: 29 | AG27: 1 | AH27: 1 | AI27: 1 | AJ27: 1
A28: 24 | B28: Implementation Consulting | C28: Implementation Consulting | D28: Sr Consultant | E28: 29 | F28: 30 | G28: 36 | AK28: 4 | AL28: 4 | AM28: 4 | AN28: 4 | AO28: 5 | AP28: 5 | AQ28: 3
A29: 25 | B29: Domestic Travel | C29: Domestic Travel for Implementation- 4 Sites South | D29: Sr Consultant | E29: 4 | F29: 30 | G29: 33 | AK29: 1 | AL29: 1 | AM29: 1 | AN29: 1
A30: 26 | B30: Implementation Consulting | C30: Implementation Consulting - End User Support | D30: Consultant 1 | E30: 35 | F30: 19 | G30: 25 | Z30: 5 | AA30: 5 | AB30: 5 | AC30: 5 | AD30: 5 | AE30: 5 | AF30: 5
A31: 27 | B31: Implementation Consulting | C31: Implementation Consulting - Application Support | D31: Consultant 1 | E31: 35 | F31: 26 | G31: 32 | AG31: 5 | AH31: 5 | AI31: 5 | AJ31: 5 | AK31: 5 | AL31: 5 | AM31: 5
A32: 28 | B32: Implementation Consulting | C32: Implementation Consulting - Field Communication Systems | D32: Consultant 1 | E32: 15 | F32: 33 | G32: 35 | AN32: 5 | AO32: 5 | AP32: 5
A33: 29 | B33: Implementation Consulting | C33: Implementation Consulting - Data Centre | D33: Consultant 2 | E33: 25 | F33: 19 | G33: 23 | Z33: 5 | AA33: 5 | AB33: 5 | AC33: 5 | AD33: 5
A34: 30 | B34: Implementation Consulting | C34: Implementation Consulting - SAP Support | D34: Consultant 2 | E34: 25 | F34: 24 | G34: 28 | AE34: 5 | AF34: 5 | AG34: 5 | AH34: 5 | AI34: 5
A35: 31 | B35: Implementation Consulting | C35: Implementation Consulting - Network Services | D35: Consultant 2 | E35: 25 | F35: 29 | G35: 33 | AJ35: 5 | AK35: 5 | AL35: 5 | AM35: 5 | AN35: 5
A36: 32 | B36: Implementation Consulting | C36: Implementation Consulting - Cyber Security Operations | D36: Consultant 2 | E36: 10 | F36: 34 | G36: 35 | AO36: 5 | AP36: 5
A37: 33 | B37: Training & Enablement | C37: Training & Enablement - Infrastructure Services | D37: SME | E37: 2 | F37: 27 | G37: 27 | AH37: 2
A38: 34 | B38: Training & Enablement | C38: Training & Enablement - End User Support | D38: SME | E38: 5 | F38: 29 | G38: 29 | AJ38: 5
A39: 35 | B39: Training & Enablement | C39: Training & Enablement - Application Support | D39: SME | E39: 5 | F39: 30 | G39: 30 | AK39: 5
A40: 36 | B40: Training & Enablement | C40: Training & Enablement - Field Communication Systems | D40: SME | E40: 2 | F40: 27 | G40: 27 | AH40: 2
A41: 37 | B41: Training & Enablement | C41: Training & Enablement - Data Centre | D41: SME | E41: 2 | F41: 27 | G41: 28 | AH41: 1 | AI41: 1
...

Sheet Resource Loading
A2: Role / Activity | B2: Source Phase | C2: Resource Type | D2: Total Planned PD | E2: W1 | F2: W2 | G2: W3 | H2: W4 | I2: W5 | J2: W6 | K2: W7 | L2: W8 | M2: W9 | N2: W10 | O2: W11 | P2: W12 | Q2: W13 | R2: W14 | S2: W15 | T2: W16 | U2: W17 | V2: W18 | W2: W19 | X2: W20 | Y2: W21 | Z2: W22 | AA2: W23 | AB2: W24 | AC2: W25 | AD2: W26 | AE2: W27 | AF2: W28 | AG2: W29 | AH2: W30 | AI2: W31 | AJ2: W32 | AK2: W33 | AL2: W34 | AM2: W35 | AN2: W36 | AO2: W37 | AP2: W38 | AQ2: W39 | AR2: W40
A3: Kick-off, scope confirmation, governance, evidence tracker and working calendar | B3: Initiation & Governance | C3: SME | D3: =SUM(E3:AR3) -> 8 | E3: 5 | F3: 3 | G3: 0 | H3: 0 | I3: 0 | J3: 0 | K3: 0 | L3: 0 | M3: 0 | N3: 0 | O3: 0 | P3: 0 | Q3: 0 | R3: 0 | S3: 0 | T3: 0 | U3: 0 | V3: 0 | W3: 0 | X3: 0 | Y3: 0 | Z3: 0 | AA3: 0 | AB3: 0 | AC3: 0 | AD3: 0 | AE3: 0 | AF3: 0 | AG3: 0 | AH3: 0 | AI3: 0 | AJ3: 0 | AK3: 0 | AL3: 0 | AM3: 0 | AN3: 0 | AO3: 0 | AP3: 0 | AQ3: 0 | AR3: 0
A4: Understand IDD operating model, service landscape, stakeholders, dependencies, suppliers and site context | B4: Understanding of PDO Ecosystem | C4: SME | D4: =SUM(E4:AR4) -> 12 | E4: 0 | F4: 2 | G4: 5 | H4: 5 | I4: 0 | J4: 0 | K4: 0 | L4: 0 | M4: 0 | N4: 0 | O4: 0 | P4: 0 | Q4: 0 | R4: 0 | S4: 0 | T4: 0 | U4: 0 | V4: 0 | W4: 0 | X4: 0 | Y4: 0 | Z4: 0 | AA4: 0 | AB4: 0 | AC4: 0 | AD4: 0 | AE4: 0 | AF4: 0 | AG4: 0 | AH4: 0 | AI4: 0 | AJ4: 0 | AK4: 0 | AL4: 0 | AM4: 0 | AN4: 0 | AO4: 0 | AP4: 0 | AQ4: 0 | AR4: 0
A5: Confirm service owners, process owners, SME participation, evidence owners and workshop calendar | B5: PDO Team Commitment and Availability for Gap Analysis | C5: SME | D5: =SUM(E5:AR5) -> 12 | E5: 0 | F5: 0 | G5: 0 | H5: 0 | I5: 5 | J5: 5 | K5: 2 | L5: 0 | M5: 0 | N5: 0 | O5: 0 | P5: 0 | Q5: 0 | R5: 0 | S5: 0 | T5: 0 | U5: 0 | V5: 0 | W5: 0 | X5: 0 | Y5: 0 | Z5: 0 | AA5: 0 | AB5: 0 | AC5: 0 | AD5: 0 | AE5: 0 | AF5: 0 | AG5: 0 | AH5: 0 | AI5: 0 | AJ5: 0 | AK5: 0 | AL5: 0 | AM5: 0 | AN5: 0 | AO5: 0 | AP5: 0 | AQ5: 0 | AR5: 0
A6: Onboarding, access readiness, evidence request follow-up, questionnaire clarification and site/audit coordination | B6: Mobilization and Engagement Readiness | C6: SME | D6: =SUM(E6:AR6) -> 22 | E6: 0 | F6: 0 | G6: 0 | H6: 0 | I6: 0 | J6: 0 | K6: 2 | L6: 5 | M6: 5 | N6: 5 | O6: 5 | P6: 0 | Q6: 0 | R6: 0 | S6: 0 | T6: 0 | U6: 0 | V6: 0 | W6: 0 | X6: 0 | Y6: 0 | Z6: 0 | AA6: 0 | AB6: 0 | AC6: 0 | AD6: 0 | AE6: 0 | AF6: 0 | AG6: 0 | AH6: 0 | AI6: 0 | AJ6: 0 | AK6: 0 | AL6: 0 | AM6: 0 | AN6: 0 | AO6: 0 | AP6: 0 | AQ6: 0 | AR6: 0
A7: Governance tracking, status reporting, issues, risks, stakeholder communication and coordination | B7: Project Management Activity | C7: SME / PM | D7: =SUM(E7:AR7) -> 69 | E7: 0 | F7: 0 | G7: 0 | H7: 0 | I7: 0 | J7: 0 | K7: 1 | L7: 0 | M7: 0 | N7: 0 | O7: 0 | P7: 3 | Q7: 0 | R7: 2 | S7: 1 | T7: 1 | U7: 1 | V7: 5 | W7: 5 | X7: 5 | Y7: 5 | Z7: 5 | AA7: 5 | AB7: 5 | AC7: 5 | AD7: 5 | AE7: 0 | AF7: 0 | AG7: 0 | AH7: 0 | AI7: 3 | AJ7: 5 | AK7: 5 | AL7: 0 | AM7: 0 | AN7: 0 | AO7: 1 | AP7: 1 | AQ7: 0 | AR7: 0
A8: Gap Assessment - Infrastructure Services | B8: Gap Assessment | C8: SME | D8: =SUM(E8:AR8) -> 2 | E8: 0 | F8: 0 | G8: 0 | H8: 0 | I8: 0 | J8: 0 | K8: 0 | L8: 0 | M8: 0 | N8: 0 | O8: 0 | P8: 2 | Q8: 0 | R8: 0 | S8: 0 | T8: 0 | U8: 0 | V8: 0 | W8: 0 | X8: 0 | Y8: 0 | Z8: 0 | AA8: 0 | AB8: 0 | AC8: 0 | AD8: 0 | AE8: 0 | AF8: 0 | AG8: 0 | AH8: 0 | AI8: 0 | AJ8: 0 | AK8: 0 | AL8: 0 | AM8: 0 | AN8: 0 | AO8: 0 | AP8: 0 | AQ8: 0 | AR8: 0
A9: Gap Assessment - End User Support | B9: Gap Assessment | C9: SME | D9: =SUM(E9:AR9) -> 8 | E9: 0 | F9: 0 | G9: 0 | H9: 0 | I9: 0 | J9: 0 | K9: 0 | L9: 0 | M9: 0 | N9: 0 | O9: 0 | P9: 0 | Q9: 5 | R9: 3 | S9: 0 | T9: 0 | U9: 0 | V9: 0 | W9: 0 | X9: 0 | Y9: 0 | Z9: 0 | AA9: 0 | AB9: 0 | AC9: 0 | AD9: 0 | AE9: 0 | AF9: 0 | AG9: 0 | AH9: 0 | AI9: 0 | AJ9: 0 | AK9: 0 | AL9: 0 | AM9: 0 | AN9: 0 | AO9: 0 | AP9: 0 | AQ9: 0 | AR9: 0
A10: Gap Assessment - Application Support | B10: Gap Assessment | C10: SME | D10: =SUM(E10:AR10) -> 2 | E10: 0 | F10: 0 | G10: 0 | H10: 0 | I10: 0 | J10: 0 | K10: 0 | L10: 0 | M10: 0 | N10: 0 | O10: 0 | P10: 0 | Q10: 0 | R10: 0 | S10: 2 | T10: 0 | U10: 0 | V10: 0 | W10: 0 | X10: 0 | Y10: 0 | Z10: 0 | AA10: 0 | AB10: 0 | AC10: 0 | AD10: 0 | AE10: 0 | AF10: 0 | AG10: 0 | AH10: 0 | AI10: 0 | AJ10: 0 | AK10: 0 | AL10: 0 | AM10: 0 | AN10: 0 | AO10: 0 | AP10: 0 | AQ10: 0 | AR10: 0
A11: Gap Assessment - Field Communication Systems | B11: Gap Assessment | C11: SME | D11: =SUM(E11:AR11) -> 2 | E11: 0 | F11: 0 | G11: 0 | H11: 0 | I11: 0 | J11: 0 | K11: 0 | L11: 0 | M11: 0 | N11: 0 | O11: 0 | P11: 0 | Q11: 0 | R11: 0 | S11: 2 | T11: 0 | U11: 0 | V11: 0 | W11: 0 | X11: 0 | Y11: 0 | Z11: 0 | AA11: 0 | AB11: 0 | AC11: 0 | AD11: 0 | AE11: 0 | AF11: 0 | AG11: 0 | AH11: 0 | AI11: 0 | AJ11: 0 | AK11: 0 | AL11: 0 | AM11: 0 | AN11: 0 | AO11: 0 | AP11: 0 | AQ11: 0 | AR11: 0
A12: Gap Assessment - Data Centre | B12: Gap Assessment | C12: SME | D12: =SUM(E12:AR12) -> 2 | E12: 0 | F12: 0 | G12: 0 | H12: 0 | I12: 0 | J12: 0 | K12: 0 | L12: 0 | M12: 0 | N12: 0 | O12: 0 | P12: 0 | Q12: 0 | R12: 0 | S12: 0 | T12: 2 | U12: 0 | V12: 0 | W12: 0 | X12: 0 | Y12: 0 | Z12: 0 | AA12: 0 | AB12: 0 | AC12: 0 | AD12: 0 | AE12: 0 | AF12: 0 | AG12: 0 | AH12: 0 | AI12: 0 | AJ12: 0 | AK12: 0 | AL12: 0 | AM12: 0 | AN12: 0 | AO12: 0 | AP12: 0 | AQ12: 0 | AR12: 0
A13: Gap Assessment - SAP Support | B13: Gap Assessment | C13: SME | D13: =SUM(E13:AR13) -> 2 | E13: 0 | F13: 0 | G13: 0 | H13: 0 | I13: 0 | J13: 0 | K13: 0 | L13: 0 | M13: 0 | N13: 0 | O13: 0 | P13: 0 | Q13: 0 | R13: 0 | S13: 0 | T13: 2 | U13: 0 | V13: 0 | W13: 0 | X13: 0 | Y13: 0 | Z13: 0 | AA13: 0 | AB13: 0 | AC13: 0 | AD13: 0 | AE13: 0 | AF13: 0 | AG13: 0 | AH13: 0 | AI13: 0 | AJ13: 0 | AK13: 0 | AL13: 0 | AM13: 0 | AN13: 0 | AO13: 0 | AP13: 0 | AQ13: 0 | AR13: 0
A14: Gap Assessment - Network Services | B14: Gap Assessment | C14: SME | D14: =SUM(E14:AR14) -> 2 | E14: 0 | F14: 0 | G14: 0 | H14: 0 | I14: 0 | J14: 0 | K14: 0 | L14: 0 | M14: 0 | N14: 0 | O14: 0 | P14: 0 | Q14: 0 | R14: 0 | S14: 0 | T14: 0 | U14: 2 | V14: 0 | W14: 0 | X14: 0 | Y14: 0 | Z14: 0 | AA14: 0 | AB14: 0 | AC14: 0 | AD14: 0 | AE14: 0 | AF14: 0 | AG14: 0 | AH14: 0 | AI14: 0 | AJ14: 0 | AK14: 0 | AL14: 0 | AM14: 0 | AN14: 0 | AO14: 0 | AP14: 0 | AQ14: 0 | AR14: 0
... A17: Policy & Procedure Optimization - End User Support | B17: Policy & Procedure Optimization | C17: Sr Consultant | D17: =SUM(E17:AR17) -> 8 | E17: 0 | F17: 0 | G17: 0 | H17: 0 | I17: 0 | J17: 0 | K17: 0 | L17: 0 | M17: 0 | N17: 0 | O17: 0 | P17: 0 | Q17: 0 | R17: 0 | S17: 0 | T17: 0 | U17: 0 | V17: 1 | W17: 5 | X17: 2 | Y17: 0 | Z17: 0 | AA17: 0 | AB17: 0 | AC17: 0 | AD17: 0 | AE17: 0 | AF17: 0 | AG17: 0 | AH17: 0 | AI17: 0 | AJ17: 0 | AK17: 0 | AL17: 0 | AM17: 0 | AN17: 0 | AO17: 0 | AP17: 0 | AQ17: 0 | AR17: 0
A18: Policy & Procedure Optimization - Application Support | B18: Policy & Procedure Optimization | C18: Sr Consultant | D18: =SUM(E18:AR18) -> 4 | E18: 0 | F18: 0 | G18: 0 | H18: 0 | I18: 0 | J18: 0 | K18: 0 | L18: 0 | M18: 0 | N18: 0 | O18: 0 | P18: 0 | Q18: 0 | R18: 0 | S18: 0 | T18: 0 | U18: 0 | V18: 0 | W18: 0 | X18: 4 | Y18: 0 | Z18: 0 | AA18: 0 | AB18: 0 | AC18: 0 | AD18: 0 | AE18: 0 | AF18: 0 | AG18: 0 | AH18: 0 | AI18: 0 | AJ18: 0 | AK18: 0 | AL18: 0 | AM18: 0 | AN18: 0 | AP18: 0 | AQ18: 0 | AR18: 0
A19: Policy & Procedure Optimization - Field Communication Systems | B19: Policy & Procedure Optimization | C19: Sr Consultant | D19: =SUM(E19:AR19) -> 4 | E19: 0 | F19: 0 | G19: 0 | H19: 0 | I19: 0 | J19: 0 | K19: 0 | L19: 0 | M19: 0 | N19: 0 | O19: 0 | P19: 0 | Q19: 0 | R19: 0 | S19: 0 | T19: 0 | U19: 0 | V19: 0 | W19: 0 | X19: 0 | Y19: 4 | Z19: 0 | AA19: 0 | AB19: 0 | AC19: 0 | AD19: 0 | AE19: 0 | AF19: 0 | AG19: 0 | AH19: 0 | AI19: 0 | AJ19: 0 | AK19: 0 | AL19: 0 | AM19: 0 | AN19: 0 | AP19: 0 | AQ19: 0 | AR19: 0
A20: Policy & Procedure Optimization - Data Centre | B20: Policy & Procedure Optimization | C20: Sr Consultant | D20: =SUM(E20:AR20) -> 4 | E20: 0 | F20: 0 | G20: 0 | H20: 0 | I20: 0 | J20: 0 | K20: 0 | L20: 0 | M20: 0 | N20: 0 | O20: 0 | P20: 0 | Q20: 0 | R20: 0 | S20: 0 | T20: 0 | U20: 0 | V20: 0 | W20: 0 | X20: 0 | Y20: 0 | Z20: 4 | AA20: 0 | AB20: 0 | AC20: 0 | AD20: 0 | AE20: 0 | AF20: 0 | AG20: 0 | AH20: 0 | AI20: 0 | AJ20: 0 | AK20: 0 | AL20: 0 | AM20: 0 | AN20: 0 | AP20: 0 | AQ20: 0 | AR20: 0
A21: Policy & Procedure Optimization - SAP Support | B21: Policy & Procedure Optimization | C21: Sr Consultant | D21: =SUM(E21:AR21) -> 4 | E21: 0 | F21: 0 | G21: 0 | H21: 0 | I21: 0 | J21: 0 | K21: 0 | L21: 0 | M21: 0 | N21: 0 | O21: 0 | P21: 0 | Q21: 0 | R21: 0 | S21: 0 | T21: 0 | U21: 0 | V21: 0 | W21: 0 | X21: 0 | Y21: 0 | Z21: 0 | AA21: 4 | AB21: 0 | AC21: 0 | AD21: 0 | AE21: 0 | AF21: 0 | AG21: 0 | AH21: 0 | AI21: 0 | AJ21: 0 | AK21: 0 | AL21: 0 | AM21: 0 | AN21: 0 | AP21: 0 | AQ21: 0 | AR21: 0
A22: Policy & Procedure Optimization - Network Services | B22: Policy & Procedure Optimization | C22: Sr Consultant | D22: =SUM(E22:AR22) -> 4 | E22: 0 | F22: 0 | G22: 0 | H22: 0 | I22: 0 | J22: 0 | K22: 0 | L22: 0 | M22: 0 | N22: 0 | O22: 0 | P22: 0 | Q22: 0 | R22: 0 | S22: 0 | T22: 0 | U22: 0 | V22: 0 | W22: 0 | X22: 0 | Y22: 0 | Z22: 0 | AA22: 0 | AB22: 4 | AC22: 0 | AD22: 0 | AE22: 0 | AF22: 0 | AG22: 0 | AH22: 0 | AI22: 0 | AJ22: 0 | AK22: 0 | AL22: 0 | AM22: 0 | AN22: 0 | AP22: 0 | AQ22: 0 | AR22: 0
A23: Policy & Procedure Optimization - Cyber Security Operations | B23: Policy & Procedure Optimization | C23: Sr Consultant | D23: =SUM(E23:AR23) -> 4 | E23: 0 | F23: 0 | G23: 0 | H23: 0 | I23: 0 | J23: 0 | K23: 0 | L23: 0 | M23: 0 | N23: 0 | O23: 0 | P23: 0 | Q23: 0 | R23: 0 | S23: 0 | T23: 0 | U23: 0 | V23: 0 | W23: 0 | X23: 0 | Y23: 0 | Z23: 0 | AA23: 0 | AB23: 0 | AC23: 4 | AD23: 0 | AE23: 0 | AF23: 0 | AG23: 0 | AH23: 0 | AI23: 0 | AJ23: 0 | AK23: 0 | AL23: 0 | AM23: 0 | AN23: 0 | AP23: 0 | AQ23: 0 | AR23: 0
A24: Implementation Consulting - Infrastructure Services | B24: Implementation Consulting | C24: Sr Consultant | D24: =SUM(E24:AR24) -> 21 | E24: 0 | F24: 0 | G24: 0 | H24: 0 | I24: 0 | J24: 0 | K24: 0 | L24: 0 | M24: 0 | N24: 0 | O24: 0 | P24: 0 | Q24: 0 | R24: 0 | S24: 0 | T24: 0 | U24: 0 | V24: 0 | W24: 0 | X24: 0 | Y24: 1 | Z24: 1 | AA24: 1 | AB24: 1 | AC24: 1 | AD24: 4 | AE24: 4 | AF24: 4 | AG24: 4 | AH24: 0 | AI24: 0 | AJ24: 0 | AK24: 0 | AL24: 0 | AM24: 0 | AN24: 0 | AP24: 0 | AQ24: 0 | AR24: 0
B25: Domestic Travel for Implementation- 4 Sites North | C25: Sr Consultant | D25: =SUM(E25:AR25) -> 4 | E25: 0 | F25: 0 | G25: 0 | H25: 0 | I25: 0 | J25: 0 | K25: 0 | L25: 0 | M25: 0 | N25: 0 | O25: 0 | P25: 0 | Q25: 0 | R25: 0 | S25: 0 | T25: 0 | U25: 0 | V25: 0 | W25: 0 | X25: 0 | Y25: 0 | Z25: 0 | AA25: 0 | AB25: 0 | AC25: 0 | AD25: 1 | AE25: 1 | AF25: 1 | AG25: 1
B26: Implementation Consulting | C26: Sr Consultant | D26: =SUM(E26:AR26) -> 29 | E26: 0 | F26: 0 | G26: 0 | H26: 0 | I26: 0 | J26: 0 | K26: 0 | L26: 0 | M26: 0 | N26: 0 | O26: 0 | P26: 0 | Q26: 0 | R26: 0 | S26: 0 | T26: 0 | U26: 0 | V26: 0 | W26: 0 | X26: 0 | Y26: 0 | Z26: 0 | AA26: 0 | AB26: 0 | AC26: 0 | AD26: 0 | AE26: 0 | AF26: 0 | AG26: 0 | AH26: 4 | AI26: 4 | AJ26: 4 | AK26: 4 | AL26: 5 | AM26: 5 | AN26: 3 | AP26: 0 | AQ26: 0 | AR26: 0
B27: Domestic Travel for Implementation- 4 Sites South | C27: Sr Consultant | D27: =SUM(E27:AR27) -> 4 | E27: 0 | F27: 0 | G27: 0 | H27: 0 | I27: 0 | J27: 0 | K27: 0 | L27: 0 | M27: 0 | N27: 0 | O27: 0 | P27: 0 | Q27: 0 | R27: 0 | S27: 0 | T27: 0 | U27: 0 | V27: 0 | W27: 0 | X27: 0 | Y27: 0 | Z27: 0 | AA27: 0 | AB27: 0 | AC27: 0 | AD27: 0 | AE27: 0 | AF27: 0 | AG27: 0 | AH27: 1 | AI27: 1 | AJ27: 1 | AK27: 1
A28: Implementation Consulting - End User Support | B28: Implementation Consulting | C28: Consultant 1 | D28: =SUM(E28:AR28) -> 35 | E28: 0 | F28: 0 | G28: 0 | H28: 0 | I28: 0 | J28: 0 | K28: 0 | L28: 0 | M28: 0 | N28: 0 | O28: 0 | P28: 0 | Q28: 0 | R28: 0 | S28: 0 | T28: 0 | U28: 0 | V28: 0 | W28: 5 | X28: 5 | Y28: 5 | Z28: 5 | AA28: 5 | AB28: 5 | AC28: 5 | AD28: 0 | AE28: 0 | AF28: 0 | AG28: 0 | AH28: 0 | AI28: 0 | AJ28: 0 | AK28: 0 | AL28: 0 | AM28: 0 | AN28: 0 | AO28: 0 | AP28: 0 | AQ28: 0 | AR28: 0
A29: Implementation Consulting - Application Support | B29: Implementation Consulting | C29: Consultant 1 | D29: =SUM(E29:AR29) -> 35 | E29: 0 | F29: 0 | G29: 0 | H29: 0 | I29: 0 | J29: 0 | K29: 0 | L29: 0 | M29: 0 | N29: 0 | O29: 0 | P29: 0 | Q29: 0 | R29: 0 | S29: 0 | T29: 0 | U29: 0 | V29: 0 | W29: 0 | X29: 0 | Y29: 0 | Z29: 0 | AA29: 0 | AB29: 0 | AC29: 0 | AD29: 5 | AE29: 5 | AF29: 5 | AG29: 5 | AH29: 5 | AI29: 5 | AJ29: 5 | AK29: 0 | AL29: 0 | AM29: 0 | AN29: 0 | AO29: 0 | AP29: 0 | AQ29: 0 | AR29: 0
A30: Implementation Consulting - Field Communication Systems | B30: Implementation Consulting | C30: Consultant 1 | D30: =SUM(E30:AR30) -> 15 | E30: 0 | F30: 0 | G30: 0 | H30: 0 | I30: 0 | J30: 0 | K30: 0 | L30: 0 | M30: 0 | N30: 0 | O30: 0 | P30: 0 | Q30: 0 | R30: 0 | S30: 0 | T30: 0 | U30: 0 | V30: 0 | W30: 0 | X30: 0 | Y30: 0 | Z30: 0 | AA30: 0 | AB30: 0 | AC30: 0 | AD30: 0 | AE30: 0 | AF30: 0 | AG30: 0 | AH30: 0 | AI30: 0 | AJ30: 0 | AK30: 5 | AL30: 5 | AM30: 5 | AN30: 0 | AO30: 0 | AP30: 0 | AQ30: 0 | AR30: 0
A31: Implementation Consulting - Data Centre | B31: Implementation Consulting | C31: Consultant 2 | D31: =SUM(E31:AR31) -> 25 | E31: 0 | F31: 0 | G31: 0 | H31: 0 | I31: 0 | J31: 0 | K31: 0 | L31: 0 | M31: 0 | N31: 0 | O31: 0 | P31: 0 | Q31: 0 | R31: 0 | S31: 0 | T31: 0 | U31: 0 | V31: 0 | W31: 5 | X31: 5 | Y31: 5 | Z31: 5 | AA31: 5 | AB31: 0 | AC31: 0 | AD31: 0 | AE31: 0 | AF31: 0 | AG31: 0 | AH31: 0 | AI31: 0 | AJ31: 0 | AK31: 0 | AL31: 0 | AM31: 0 | AN31: 0 | AO31: 0 | AP31: 0 | AQ31: 0 | AR31: 0
A32: Implementation Consulting - SAP Support | B32: Implementation Consulting | C32: Consultant 2 | D32: =SUM(E32:AR32) -> 25 | E32: 0 | F32: 0 | G32: 0 | H32: 0 | I32: 0 | J32: 0 | K32: 0 | L32: 0 | M32: 0 | N32: 0 | O32: 0 | P32: 0 | Q32: 0 | R32: 0 | S32: 0 | T32: 0 | U32: 0 | V32: 0 | W32: 0 | X32: 0 | Y32: 0 | Z32: 0 | AA32: 0 | AB32: 5 | AC32: 5 | AD32: 5 | AE32: 5 | AF32: 5 | AG32: 0 | AH32: 0 | AI32: 0 | AJ32: 0 | AK32: 0 | AL32: 0 | AM32: 0 | AN32: 0 | AO32: 0 | AP32: 0 | AQ32: 0 | AR32: 0
A33: Implementation Consulting - Network Services | B33: Implementation Consulting | C33: Consultant 2 | D33: =SUM(E33:AR33) -> 25 | E33: 0 | F33: 0 | G33: 0 | H33: 0 | I33: 0 | J33: 0 | K33: 0 | L33: 0 | M33: 0 | N33: 0 | O33: 0 | P33: 0 | Q33: 0 | R33: 0 | S33: 0 | T33: 0 | U33: 0 | V33: 0 | W33: 0 | X33: 0 | Y33: 0 | Z33: 0 | AA33: 0 | AB33: 0 | AC33: 0 | AD33: 0 | AE33: 0 | AF33: 0 | AG33: 5 | AH33: 5 | AI33: 5 | AJ33: 5 | AK33: 5 | AL33: 0 | AM33: 0 | AN33: 0 | AO33: 0 | AP33: 0 | AQ33: 0 | AR33: 0
A34: Implementation Consulting - Cyber Security Operations | B34: Implementation Consulting | C34: Consultant 2 | D34: =SUM(E34:AR34) -> 10 | E34: 0 | F34: 0 | G34: 0 | H34: 0 | I34: 0 | J34: 0 | K34: 0 | L34: 0 | M34: 0 | N34: 0 | O34: 0 | P34: 0 | Q34: 0 | R34: 0 | S34: 0 | T34: 0 | U34: 0 | V34: 0 | W34: 0 | X34: 0 | Y34: 0 | Z34: 0 | AA34: 0 | AB34: 0 | AC34: 0 | AD34: 0 | AE34: 0 | AF34: 0 | AG34: 0 | AH34: 0 | AI34: 0 | AJ34: 0 | AK34: 0 | AL34: 5 | AM34: 5 | AN34: 0 | AO34: 0 | AP34: 0 | AQ34: 0 | AR34: 0
A35: Training & Enablement - Infrastructure Services | B35: Training & Enablement | C35: SME | D35: =SUM(E35:AR35) -> 2 | E35: 0 | F35: 0 | G35: 0 | H35: 0 | I35: 0 | J35: 0 | K35: 0 | L35: 0 | M35: 0 | N35: 0 | O35: 0 | P35: 0 | Q35: 0 | R35: 0 | S35: 0 | T35: 0 | U35: 0 | V35: 0 | W35: 0 | X35: 0 | Y35: 0 | Z35: 0 | AA35: 0 | AB35: 0 | AC35: 0 | AD35: 0 | AE35: 2 | AF35: 0 | AG35: 0 | AH35: 0 | AI35: 0 | AJ35: 0 | AK35: 0 | AL35: 0 | AM35: 0 | AN35: 0 | AO35: 0 | AP35: 0 | AQ35: 0 | AR35: 0
A36: Training & Enablement - End User Support | B36: Training & Enablement | C36: SME | D36: =SUM(E36:AR36) -> 5 | E36: 0 | F36: 0 | G36: 0 | H36: 0 | I36: 0 | J36: 0 | K36: 0 | L36: 0 | M36: 0 | N36: 0 | O36: 0 | P36: 0 | Q36: 0 | R36: 0 | S36: 0 | T36: 0 | U36: 0 | V36: 0 | W36: 0 | X36: 0 | Y36: 0 | Z36: 0 | AA36: 0 | AB36: 0 | AC36: 0 | AD36: 0 | AE36: 0 | AF36: 0 | AG36: 5 | AH36: 0 | AI36: 0 | AJ36: 0 | AK36: 0 | AL36: 0 | AM36: 0 | AN36: 0 | AO36: 0 | AP36: 0 | AQ36: 0 | AR36: 0
A37: Training & Enablement - Application Support | B37: Training & Enablement | C37: SME | D37: =SUM(E37:AR37) -> 5 | E37: 0 | F37: 0 | G37: 0 | H37: 0 | I37: 0 | J37: 0 | K37: 0 | L37: 0 | M37: 0 | N37: 0 | O37: 0 | P37: 0 | Q37: 0 | R37: 0 | S37: 0 | T37: 0 | U37: 0 | V37: 0 | W37: 0 | X37: 0 | Y37: 0 | Z37: 0 | AA37: 0 | AB37: 0 | AC37: 0 | AD37: 0 | AE37: 0 | AF37: 0 | AG37: 0 | AH37: 5 | AI37: 0 | AJ37: 0 | AK37: 0 | AL37: 0 | AM37: 0 | AN37: 0 | AO37: 0 | AP37: 0 | AQ37: 0 | AR37: 0
A38: Training & Enablement - Field Communication Systems | B38: Training & Enablement | C38: SME | D38: =SUM(E38:AR38) -> 2 | E38: 0 | F38: 0 | G38: 0 | H38: 0 | I38: 0 | J38: 0 | K38: 0 | L38: 0 | M38: 0 | N38: 0 | O38: 0 | P38: 0 | Q38: 0 | R38: 0 | S38: 0 | T38: 0 | U38: 0 | V38: 0 | W38: 0 | X38: 0 | Y38: 0 | Z38: 0 | AA38: 0 | AB38: 0 | AC38: 0 | AD38: 0 | AE38: 2 | AF38: 0 | AG38: 0 | AH38: 0 | AI38: 0 | AJ38: 0 | AK38: 0 | AL38: 0 | AM38: 0 | AN38: 0 | AO38: 0 | AP38: 0 | AQ38: 0 | AR38: 0
A39: Training & Enablement - Data Centre | B39: Training & Enablement | C39: SME | D39: =SUM(E39:AR39) -> 2 | E39: 0 | F39: 0 | G39: 0 | H39: 0 | I39: 0 | J39: 0 | K39: 0 | L39: 0 | M39: 0 | N39: 0 | O39: 0 | P39: 0 | Q39: 0 | R39: 0 | S39: 0 | T39: 0 | U39: 0 | V39: 0 | W39: 0 | X39: 0 | Y39: 0 | Z39: 0 | AA39: 0 | AB39: 0 | AC39: 0 | AD39: 0 | AE39: 1 | AF39: 1 | AG39: 0 | AH39: 0 | AI39: 0 | AJ39: 0 | AK39: 0 | AL39: 0 | AM39: 0 | AN39: 0 | AO39: 0 | AP39: 0 | AQ39: 0 | AR39: 0
... A44: Internal Audit & Readiness - End User Support | B44: Internal Audit & Readiness | C44: SME | D44: =SUM(E44:AR44) -> 5 | E44: 0 | F44: 0 | G44: 0 | H44: 0 | I44: 0 | J44: 0 | K44: 0 | L44: 0 | M44: 0 | N44: 0 | O44: 0 | P44: 0 | Q44: 0 | R44: 0 | S44: 0 | T44: 0 | U44: 0 | V44: 0 | W44: 0 | X44: 0 | Y44: 0 | Z44: 0 | AA44: 0 | AB44: 0 | AC44: 0 | AD44: 0 | AE44: 0 | AF44: 0 | AG44: 0 | AH44: 0 | AI44: 0 | AJ44: 0 | AK44: 0 | AL44: 0 | AM44: 0 | AN44: 3 | AO44: 2 | AP44: 0 | AQ44: 0 | AR44: 0
B45: Domestic Travel for Internal Audit- 4 Sites North | C45: SME | D45: =SUM(E45:AR45) -> 4 | E45: 0 | F45: 0 | G45: 0 | H45: 0 | I45: 0 | J45: 0 | K45: 0 | L45: 0 | M45: 0 | N45: 0 | O45: 0 | P45: 0 | Q45: 0 | R45: 0 | S45: 0 | T45: 0 | U45: 0 | V45: 0 | W45: 0 | X45: 0 | Y45: 0 | Z45: 0 | AA45: 0 | AB45: 0 | AC45: 0 | AD45: 0 | AE45: 0 | AF45: 0 | AG45: 0 | AH45: 0 | AI45: 0 | AN45: 2 | AO45: 2
A46: Internal Audit & Readiness - Application Support | B46: Internal Audit & Readiness | C46: SME | D46: =SUM(E46:AR46) -> 5 | E46: 0 | F46: 0 | G46: 0 | H46: 0 | I46: 0 | J46: 0 | K46: 0 | L46: 0 | M46: 0 | N46: 0 | O46: 0 | P46: 0 | Q46: 0 | R46: 0 | S46: 0 | T46: 0 | U46: 0 | V46: 0 | W46: 0 | X46: 0 | Y46: 0 | Z46: 0 | AA46: 0 | AB46: 0 | AC46: 0 | AD46: 0 | AE46: 0 | AF46: 0 | AG46: 0 | AH46: 0 | AI46: 0 | AJ46: 0 | AK46: 0 | AL46: 0 | AM46: 0 | AN46: 3 | AO46: 2 | AP46: 0 | AQ46: 0 | AR46: 0
B47: Domestic Travel for Implementation- 4 Sites South | C47: SME | D47: =SUM(E47:AR47) -> 4 | E47: 0 | F47: 0 | G47: 0 | H47: 0 | I47: 0 | J47: 0 | K47: 0 | L47: 0 | M47: 0 | N47: 0 | O47: 0 | P47: 0 | Q47: 0 | R47: 0 | S47: 0 | T47: 0 | U47: 0 | V47: 0 | W47: 0 | X47: 0 | Y47: 0 | Z47: 0 | AA47: 0 | AB47: 0 | AC47: 0 | AD47: 0 | AE47: 0 | AF47: 0 | AG47: 0 | AH47: 0 | AI47: 0 | AJ47: 0 | AK47: 0 | AL47: 0 | AN47: 2 | AO47: 2
...

Sheet Milestone Cost Tracking
A1: Milestone Cost Tracking - PDO ISO/IEC 20000-1 Project Plan
A4: Milestone ID | B4: Milestone Phase | C4: Included Activities / Scope | D4: Start Week | E4: End Week | F4: Start Date | G4: End Date | H4: Payment Milestone % | I4: Planned Invoice Amount - Oman | J4: Planned Invoice Amount - India | K4: Invoice Status
A5: M1 | B5: Initiation & Governance | C5: Initiation & Governance | D5: 1 | E5: 2 | F5: 46281 | G5: 46285 | H5: 0.1 | I5: =Estimation!P61*H5 -> 13578.95 | J5: =Estimation!P62*H5 -> 10075.45 | K5: Planned
A6: M2 | B6: Gap Assessment & Baseline Readiness | C6: Gap Assessment | D6: 12 | E6: 17 | F6: 46358 | G6: 46397 | H6: 0.3 | I6: =H6*Estimation!P61 -> 40736.85 | J6: =H6*Estimation!P62 -> 30226.35 | K6: Planned
A7: M3 | B7: Policy & Procedure Optimization | C7: Policy & Procedure Optimization | D7: 18 | E7: 25 | F7: 46400 | G7: 46453 | H7: 0.2 | I7: =H7*Estimation!P61 -> 27157.9 | J7: =H7*Estimation!P62 -> 20150.9 | K7: Planned
A8: M4 | B8: Implementation Support | C8: Implementation Consulting | D8: 16 | E8: 40 | F8: 46386 | G8: 46558 | H8: 0.2 | I8: =H8*Estimation!P61 -> 27157.9 | J8: =H8*Estimation!P62 -> 20150.9 | K8: Planned
A9: M5 | B9: Internal Audit Completion | C9: Internal Audit Completion | D9: 27 | E9: 38 | F9: 46463 | G9: 46544 | H9: 0.1 | I9: =H9*Estimation!P61 -> 13578.95 | J9: =H9*Estimation!P62 -> 10075.45 | K9: Planned
A10: M6 | B10: Certification Support & Closure | C10: Certification Support; Domestic Travel | D10: 39 | E10: 40 | F10: 46547 | G10: 46558 | H10: 0.1 | I10: =H10*Estimation!P61 -> 13578.95 | J10: =H10*Estimation!P62 -> 10075.45 | K10: Planned
A11: TOTAL | I11: =SUM(I5:I10) -> 135789.5 | J11: =SUM(J5:J10) -> 100754.5

Sheet Estimation
A1: PDO ISO/IEC 20000-1 Estimation
A4: Global Inputs
A5: Project Start Date | C5: Editable start date
A6: Total Project Duration | B6: 40 Weeks | C6: Overall schedule- 40 Weeks
A7: SME Rate - Oman Resource (OMR/PD) | B7: 200 | C7: Lead Consultant / ISO 20000 SME
A8: Consultant Rate - Oman Resource (OMR/PD) | B8: 125 | C8: Implementation / documentation consultant
A9: Omani Trainee Rate (OMR/PD) | B9: 30 | C9: Assumed rate for two Omani trainees
A10: SME Rate - Indian Resource (OMR/PD) | B10: 100 | C10: Indian Resource
A11: Consultant Rate - Indian Resource (OMR/PD) | B11: 75 | C11: Indian Resource
A12: Travel / Logistics - Oman Resource (OMR) per Resource | B12: 500 | C12: Local logistics placeholder
A13: Travel / Logistics - Indian Resource (OMR) per Resource | B13: 3600 | C13: Room 3000 + Travel 600 as per prior assumption
A14: Domestic To and Fro charge through Air per Travel | B14: 200 | C14: Total 4 Sites. One domestic Air travel will be done and other sites will be connected through road transport.
A15: # of Domestic Air Travels | B15: 2 | C15: Travel to North and South through Air and use Road Transport for reaching other 3 sites.
A16: # of Domestic Trips | B16: 3 | C16: 3 Travels - 1 for implementation, 1 for Internal Audit and 1 External Audit
A17: Total Domestic Travel Expense (Air & Road Transport) | B17: =(B16*B14)*B15 -> 1200 | C17: Domestic travel expense based on 3 travel cycles. Additive to base travel/logistics in commercial summary.
A18: Domestic Local Road Travel Effort - 8 Sites | B18: =8 -> 8 | C18: 8 sites x 1 PD local road travel per site = 8 PD. Effort is included in SME effort and costed separately for visibility.
A19: Contingency % | B19: 0.1 | C19: Applied to consulting costs
A20: Certification Body Cost Placeholder (OMR) | C20: PDO Scope
A21: Currency | B21: OMR | C21: Commercial currency
A23: S.No | B23: Service Name | C23: Resource Input | D23: Service Description | E23: Gap Analysis PD | F23: Policy & Procedure PD | G23: Implementation PD | H23: Training PD | I23: Internal Audit PD | J23: Certification Support PD | K23: Total Service PD | L23: Remarks
A24: 1 | B24: Infrastructure Services | C24: 15+ | D24: Hosting, Database, Storage, Back-up, AD, etc. | E24: 2 | F24: 4 | G24: 25 | H24: 2 | I24: 2 | J24: 2 | K24: =SUM(E24:J24) -> 37 | L24: Service effort as per given input.
A25: 2 | B25: End User Support | C25: 50+ | D25: ServiceDesk & Hardware & Asset Management | E25: 5 | F25: 6 | G25: 35 | H25: 5 | I25: 5 | J25: 5 | K25: =SUM(E25:J25) -> 61 | L25: Service effort as per given input.
A26: 3 | B26: Cloud Services | C26: Scattered across Apps Team | D26: Cloud Hosting coordination services | E26: 0 | F26: 0 | G26: 0 | H26: 0 | I26: 0 | J26: 0 | K26: =SUM(E26:J26) -> 0 | L26: Zero effort per input; included in Application Support / not separately estimated.
A27: 4 | B27: Application Support | C27: 50+ (incl. Contractors) | D27: App Development, testing, run & maintain | E27: 5 | F27: 6 | G27: 35 | H27: 5 | I27: 5 | J27: 5 | K27: =SUM(E27:J27) -> 61 | L27: Service effort as per given input.
A28: 5 | B28: Field Communication Systems | C28: 10+ | D28: WiMAX & Tetra Services | E28: 2 | F28: 4 | G28: 25 | H28: 2 | I28: 2 | J28: 2 | K28: =SUM(E28:J28) -> 37 | L28: Service effort as per given input.
A29: 6 | B29: Data Centre | C29: 7+ | D29: Data Center Facilities/Infrastructure Management & Monitoring | E29: 2 | F29: 4 | G29: 25 | H29: 2 | I29: 2 | J29: 2 | K29: =SUM(E29:J29) -> 37 | L29: Service effort as per given input.
A30: 7 | B30: SAP Support | C30: 15+ | D30: SAP Basis & ABAP | E30: 2 | F30: 4 | G30: 25 | H30: 2 | I30: 2 | J30: 2 | K30: =SUM(E30:J30) -> 37 | L30: Service effort as per given input.
A31: 8 | B31: Network Services | C31: 5+ | D31: Network & Voice Collaborations | E31: 2 | F31: 4 | G31: 25 | H31: 2 | I31: 2 | J31: 2 | K31: =SUM(E31:J31) -> 37 | L31: Service effort as per given input.
A32: 9 | B32: Digital Platforms | C32: Included in App Support | D32: NA | E32: 0 | F32: 0 | G32: 0 | H32: 0 | I32: 0 | J32: 0 | K32: =SUM(E32:J32) -> 0 | L32: Zero effort per input; included in Application Support / not separately estimated.
A33: 10 | B33: Cyber Security Operations | C33: 15+ | D33: SOC, End-Point Sec, Threat Intell, etc. | E33: 2 | F33: 4 | G33: 25 | H33: 2 | I33: 2 | J33: 2 | K33: =SUM(E33:J33) -> 37 | L33: Service effort as per given input.
E34: =SUM(E24:E33) -> 22 | F34: =SUM(F24:F33) -> 36 | G34: =SUM(G24:G33) -> 220 | H34: =SUM(H24:H33) -> 22 | I34: =SUM(I24:I33) -> 22 | J34: =SUM(J24:J33) -> 22 | K34: =SUM(K24:K33) -> 344
A36: Program Management Effort
A37: ID | B37: Program Management | C37: Scope | D37: Description | E37: Effort PD | F37: Resource Type
A38: C1 | B38: Project Initiation & Governance | C38: All services | D38: Kick-off, scope confirmation, governance, evidence tracker and schedule planning. | E38: 8 | F38: SME
A39: C2 | B39: Understanding of PDO Ecosystem | C39: All services | D39: Understand PDO organization context, IDD operating model, service landscape, stakeholder structure, technology ecosystem, supplier interfaces, service dependencies and site context before formal gap assessment. | E39: 12 | F39: SME
A40: C3 | B40: PDO Team Commitment and Availability for Gap Analysis | C40: All services | D40: Obtain management and team commitment for gap assessment workshops, confirm PDO SME availability, service owner participation, process owner nominations, evidence owners and workshop calendar. | E40: 12 | F40: SME
A41: C4 | B41: Mobilization and Engagement Readiness | C41: All services | D41: Mobilization covers onboarding, access readiness, evidence request follow-up, questionnaire clarification, detailed schedule finalization, site/audit coordination and readiness for gap analysis. | E41: 22 | F41: SME
A42: C5 | B42: Management Review Facilitation | C42: All services | D42: Management review preparation, facilitation, minutes and action tracking. | E42: 4 | F42: SME
A43: C6 | B43: Project Tracking | C43: All services | D43: Project management, governance tracking, coordination, status reporting, issue/risk follow-up and stakeholder communication. | E43: 69 | F43: SME
A44: C7 | B44: Two Omani Trainees during Implementation | C44: Implementation phase | D44: 2 trainees x 5 PD/week x 25 weeks for implementation assistance and knowledge transfer. | E44: 250 | F44: Omani Trainee
...
